Workbook

Sheet Summary
A1: POWER PARK STUDENT HOUSING — PHASE 3
A2: Inspection Points to Visit — Project Summary
A3: 190 four-bed units · 3 blocks · snapshot 09 Jun 2026 (DB SNAP 2026-06-09 09:59 UTC)
A5: TOTAL SCOPE | C5: PASSED (OK) | E5: % PASSED | G5: POINTS TO VISIT | I5: TRULY CERTIFIED
A6: ='190-Unit Detail'!F194 -> 95716 | C6: ='190-Unit Detail'!G194 -> 83046 | E6: ='190-Unit Detail'!G194/'190-Unit Detail'!F194 -> 0.86762924 | G6: ='190-Unit Detail'!N194 -> 12739 | I6: =COUNTIFS('190-Unit Detail'!N4:N193,0) -> 2
A7: inspection points | C7: points marked MS/OK | E7: of total scope | G7: on-site actions remaining | I7: units, every axis clean
A9: WHAT REMAINS (the Points to Visit)
A10: Pending — not yet inspected | D10: ='190-Unit Detail'!H194 -> 5881
A11: NTS — failed, awaiting re-mark | D11: ='190-Unit Detail'!I194 -> 2140
A12: Not installed | D12: ='190-Unit Detail'!J194 -> 12
A13: Skipped — previously excluded, now in scope | D13: ='190-Unit Detail'!K194 -> 4637
A14: Items to Mark (subtotal) | D14: ='190-Unit Detail'!L194 -> 12670
A15: Latent defects to rectify | D15: ='190-Unit Detail'!M194 -> 69
A16: POINTS TO VISIT (Items to Mark + Latents) | D16: ='190-Unit Detail'!N194 -> 12739
A17: Reconciliation check: Passed + Items to Mark = Total Scope → | D17: ='190-Unit Detail'!G194+'190-Unit Detail'!L194 -> 95716
A19: BLOCK ROLLUP
A20: Block | C20: Units | D20: Total Points | E20: Passed | F20: % Passed | G20: Points to Visit
A21: Block 1 | C21: =COUNTIFS('190-Unit Detail'!B4:B193,"Block 1") -> 8 | D21: =SUMIFS('190-Unit Detail'!F4:F193,'190-Unit Detail'!B4:B193,"Block 1") -> 4016 | E21: =SUMIFS('190-Unit Detail'!G4:G193,'190-Unit Detail'!B4:B193,"Block 1") -> 3457 | F21: =IF(SUMIFS('190-Unit Detail'!F4:F193,'190-Unit Detail'!B4:B193,"Block 1")=0,0,SUMIFS('190-Unit Detail'!G4:G193,'190-Unit Detail'!B4:B193,"Block 1")/SUMIFS('190-Unit Detail'!F4:F193,'190-Unit Detail'!B4:B193,"Block 1")) -> 0.86080677 | G21: =SUMIFS('190-Unit Detail'!N4:N193,'190-Unit Detail'!B4:B193,"Block 1") -> 560
A22: Block 2 | C22: =COUNTIFS('190-Unit Detail'!B4:B193,"Block 2") -> 8 | D22: =SUMIFS('190-Unit Detail'!F4:F193,'190-Unit Detail'!B4:B193,"Block 2") -> 4016 | E22: =SUMIFS('190-Unit Detail'!G4:G193,'190-Unit Detail'!B4:B193,"Block 2") -> 3217 | F22: =IF(SUMIFS('190-Unit Detail'!F4:F193,'190-Unit Detail'!B4:B193,"Block 2")=0,0,SUMIFS('190-Unit Detail'!G4:G193,'190-Unit Detail'!B4:B193,"Block 2")/SUMIFS('190-Unit Detail'!F4:F193,'190-Unit Detail'!B4:B193,"Block 2")) -> 0.80104582 | G22: =SUMIFS('190-Unit Detail'!N4:N193,'190-Unit Detail'!B4:B193,"Block 2") -> 799
A23: Block 3 | C23: =COUNTIFS('190-Unit Detail'!B4:B193,"Block 3") -> 37 | D23: =SUMIFS('190-Unit Detail'!F4:F193,'190-Unit Detail'!B4:B193,"Block 3") -> 18640 | E23: =SUMIFS('190-Unit Detail'!G4:G193,'190-Unit Detail'!B4:B193,"Block 3") -> 16350 | F23: =IF(SUMIFS('190-Unit Detail'!F4:F193,'190-Unit Detail'!B4:B193,"Block 3")=0,0,SUMIFS('190-Unit Detail'!G4:G193,'190-Unit Detail'!B4:B193,"Block 3")/SUMIFS('190-Unit Detail'!F4:F193,'190-Unit Detail'!B4:B193,"Block 3")) -> 0.87714592 | G23: =SUMIFS('190-Unit Detail'!N4:N193,'190-Unit Detail'!B4:B193,"Block 3") -> 2296
A24: Block 4 | C24: =COUNTIFS('190-Unit Detail'!B4:B193,"Block 4") -> 42 | D24: =SUMIFS('190-Unit Detail'!F4:F193,'190-Unit Detail'!B4:B193,"Block 4") -> 21168 | E24: =SUMIFS('190-Unit Detail'!G4:G193,'190-Unit Detail'!B4:B193,"Block 4") -> 18271 | F24: =IF(SUMIFS('190-Unit Detail'!F4:F193,'190-Unit Detail'!B4:B193,"Block 4")=0,0,SUMIFS('190-Unit Detail'!G4:G193,'190-Unit Detail'!B4:B193,"Block 4")/SUMIFS('190-Unit Detail'!F4:F193,'190-Unit Detail'!B4:B193,"Block 4")) -> 0.86314248 | G24: =SUMIFS('190-Unit Detail'!N4:N193,'190-Unit Detail'!B4:B193,"Block 4") -> 2930
A25: Block 5 | C25: =COUNTIFS('190-Unit Detail'!B4:B193,"Block 5") -> 42 | D25: =SUMIFS('190-Unit Detail'!F4:F193,'190-Unit Detail'!B4:B193,"Block 5") -> 21168 | E25: =SUMIFS('190-Unit Detail'!G4:G193,'190-Unit Detail'!B4:B193,"Block 5") -> 18964 | F25: =IF(SUMIFS('190-Unit Detail'!F4:F193,'190-Unit Detail'!B4:B193,"Block 5")=0,0,SUMIFS('190-Unit Detail'!G4:G193,'190-Unit Detail'!B4:B193,"Block 5")/SUMIFS('190-Unit Detail'!F4:F193,'190-Unit Detail'!B4:B193,"Block 5")) -> 0.89588057 | G25: =SUMIFS('190-Unit Detail'!N4:N193,'190-Unit Detail'!B4:B193,"Block 5") -> 2204
A26: Block 6 | C26: =COUNTIFS('190-Unit Detail'!B4:B193,"Block 6") -> 36 | D26: =SUMIFS('190-Unit Detail'!F4:F193,'190-Unit Detail'!B4:B193,"Block 6") -> 18144 | E26: =SUMIFS('190-Unit Detail'!G4:G193,'190-Unit Detail'!B4:B193,"Block 6") -> 15832 | F26: =IF(SUMIFS('190-Unit Detail'!F4:F193,'190-Unit Detail'!B4:B193,"Block 6")=0,0,SUMIFS('190-Unit Detail'!G4:G193,'190-Unit Detail'!B4:B193,"Block 6")/SUMIFS('190-Unit Detail'!F4:F193,'190-Unit Detail'!B4:B193,"Block 6")) -> 0.87257496 | G26: =SUMIFS('190-Unit Detail'!N4:N193,'190-Unit Detail'!B4:B193,"Block 6") -> 2338
A27: Block 7 | C27: =COUNTIFS('190-Unit Detail'!B4:B193,"Block 7") -> 17 | D27: =SUMIFS('190-Unit Detail'!F4:F193,'190-Unit Detail'!B4:B193,"Block 7") -> 8564 | E27: =SUMIFS('190-Unit Detail'!G4:G193,'190-Unit Detail'!B4:B193,"Block 7") -> 6955 | F27: =IF(SUMIFS('190-Unit Detail'!F4:F193,'190-Unit Detail'!B4:B193,"Block 7")=0,0,SUMIFS('190-Unit Detail'!G4:G193,'190-Unit Detail'!B4:B193,"Block 7")/SUMIFS('190-Unit Detail'!F4:F193,'190-Unit Detail'!B4:B193,"Block 7")) -> 0.8121205 | G27: =SUMIFS('190-Unit Detail'!N4:N193,'190-Unit Detail'!B4:B193,"Block 7") -> 1612
A28: TOTAL | C28: =SUM(C21:C27) -> 190 | D28: =SUM(D21:D27) -> 95716 | E28: =SUM(E21:E27) -> 83046 | F28: =IF(D28=0,0,E28/D28) -> 0.86762924 | G28: =SUM(G21:G27) -> 12739
A30: BLOCK x FLOOR GRID
A31: Block | B31: Floor | C31: Units | D31: Total Points | E31: Passed | F31: % Passed | G31: Points to Visit
A32: Block 1 | B32: 1 | C32: =COUNTIFS('190-Unit Detail'!B4:B193,"Block 1",'190-Unit Detail'!C4:C193,1) -> 2 | D32: =SUMIFS('190-Unit Detail'!F4:F193,'190-Unit Detail'!B4:B193,"Block 1",'190-Unit Detail'!C4:C193,1) -> 1004 | E32: =SUMIFS('190-Unit Detail'!G4:G193,'190-Unit Detail'!B4:B193,"Block 1",'190-Unit Detail'!C4:C193,1) -> 954 | F32: =IF(SUMIFS('190-Unit Detail'!F4:F193,'190-Unit Detail'!B4:B193,"Block 1",'190-Unit Detail'!C4:C193,1)=0,0,SUMIFS('190-Unit Detail'!G4:G193,'190-Unit Detail'!B4:B193,"Block 1",'190-Unit Detail'!C4:C193,1)/SUMIFS('190-Unit Detail'!F4:F193,'190-Unit Detail'!B4:B193,"Block 1",'190-Unit Detail'!C4:C193,1)) -> 0.9501992 | G32: =SUMIFS('190-Unit Detail'!N4:N193,'190-Unit Detail'!B4:B193,"Block 1",'190-Unit Detail'!C4:C193,1) -> 50
A33: Block 1 | B33: 2 | C33: =COUNTIFS('190-Unit Detail'!B4:B193,"Block 1",'190-Unit Detail'!C4:C193,2) -> 6 | D33: =SUMIFS('190-Unit Detail'!F4:F193,'190-Unit Detail'!B4:B193,"Block 1",'190-Unit Detail'!C4:C193,2) -> 3012 | E33: =SUMIFS('190-Unit Detail'!G4:G193,'190-Unit Detail'!B4:B193,"Block 1",'190-Unit Detail'!C4:C193,2) -> 2503 | F33: =IF(SUMIFS('190-Unit Detail'!F4:F193,'190-Unit Detail'!B4:B193,"Block 1",'190-Unit Detail'!C4:C193,2)=0,0,SUMIFS('190-Unit Detail'!G4:G193,'190-Unit Detail'!B4:B193,"Block 1",'190-Unit Detail'!C4:C193,2)/SUMIFS('190-Unit Detail'!F4:F193,'190-Unit Detail'!B4:B193,"Block 1",'190-Unit Detail'!C4:C193,2)) -> 0.8310093 | G33: =SUMIFS('190-Unit Detail'!N4:N193,'190-Unit Detail'!B4:B193,"Block 1",'190-Unit Detail'!C4:C193,2) -> 510
A34: Block 2 | B34: 1 | C34: =COUNTIFS('190-Unit Detail'!B4:B193,"Block 2",'190-Unit Detail'!C4:C193,1) -> 4 | D34: =SUMIFS('190-Unit Detail'!F4:F193,'190-Unit Detail'!B4:B193,"Block 2",'190-Unit Detail'!C4:C193,1) -> 2008 | E34: =SUMIFS('190-Unit Detail'!G4:G193,'190-Unit Detail'!B4:B193,"Block 2",'190-Unit Detail'!C4:C193,1) -> 1524 | F34: =IF(SUMIFS('190-Unit Detail'!F4:F193,'190-Unit Detail'!B4:B193,"Block 2",'190-Unit Detail'!C4:C193,1)=0,0,SUMIFS('190-Unit Detail'!G4:G193,'190-Unit Detail'!B4:B193,"Block 2",'190-Unit Detail'!C4:C193,1)/SUMIFS('190-Unit Detail'!F4:F193,'190-Unit Detail'!B4:B193,"Block 2",'190-Unit Detail'!C4:C193,1)) -> 0.75896414 | G34: =SUMIFS('190-Unit Detail'!N4:N193,'190-Unit Detail'!B4:B193,"Block 2",'190-Unit Detail'!C4:C193,1) -> 484
A35: Block 2 | B35: 2 | C35: =COUNTIFS('190-Unit Detail'!B4:B193,"Block 2",'190-Unit Detail'!C4:C193,2) -> 4 | D35: =SUMIFS('190-Unit Detail'!F4:F193,'190-Unit Detail'!B4:B193,"Block 2",'190-Unit Detail'!C4:C193,2) -> 2008 | E35: =SUMIFS('190-Unit Detail'!G4:G193,'190-Unit Detail'!B4:B193,"Block 2",'190-Unit Detail'!C4:C193,2) -> 1693 | F35: =IF(SUMIFS('190-Unit Detail'!F4:F193,'190-Unit Detail'!B4:B193,"Block 2",'190-Unit Detail'!C4:C193,2)=0,0,SUMIFS('190-Unit Detail'!G4:G193,'190-Unit Detail'!B4:B193,"Block 2",'190-Unit Detail'!C4:C193,2)/SUMIFS('190-Unit Detail'!F4:F193,'190-Unit Detail'!B4:B193,"Block 2",'190-Unit Detail'!C4:C193,2)) -> 0.84312749 | G35: =SUMIFS('190-Unit Detail'!N4:N193,'190-Unit Detail'!B4:B193,"Block 2",'190-Unit Detail'!C4:C193,2) -> 315
A36: Block 3 | B36: 0 | C36: =COUNTIFS('190-Unit Detail'!B4:B193,"Block 3",'190-Unit Detail'!C4:C193,0) -> 11 | D36: =SUMIFS('190-Unit Detail'!F4:F193,'190-Unit Detail'!B4:B193,"Block 3",'190-Unit Detail'!C4:C193,0) -> 5588 | E36: =SUMIFS('190-Unit Detail'!G4:G193,'190-Unit Detail'!B4:B193,"Block 3",'190-Unit Detail'!C4:C193,0) -> 4852 | F36: =IF(SUMIFS('190-Unit Detail'!F4:F193,'190-Unit Detail'!B4:B193,"Block 3",'190-Unit Detail'!C4:C193,0)=0,0,SUMIFS('190-Unit Detail'!G4:G193,'190-Unit Detail'!B4:B193,"Block 3",'190-Unit Detail'!C4:C193,0)/SUMIFS('190-Unit Detail'!F4:F193,'190-Unit Detail'!B4:B193,"Block 3",'190-Unit Detail'!C4:C193,0)) -> 0.86828919 | G36: =SUMIFS('190-Unit Detail'!N4:N193,'190-Unit Detail'!B4:B193,"Block 3",'190-Unit Detail'!C4:C193,0) -> 742
A37: Block 3 | B37: 1 | C37: =COUNTIFS('190-Unit Detail'!B4:B193,"Block 3",'190-Unit Detail'!C4:C193,1) -> 13 | D37: =SUMIFS('190-Unit Detail'!F4:F193,'190-Unit Detail'!B4:B193,"Block 3",'190-Unit Detail'!C4:C193,1) -> 6526 | E37: =SUMIFS('190-Unit Detail'!G4:G193,'190-Unit Detail'!B4:B193,"Block 3",'190-Unit Detail'!C4:C193,1) -> 6014 | F37: =IF(SUMIFS('190-Unit Detail'!F4:F193,'190-Unit Detail'!B4:B193,"Block 3",'190-Unit Detail'!C4:C193,1)=0,0,SUMIFS('190-Unit Detail'!G4:G193,'190-Unit Detail'!B4:B193,"Block 3",'190-Unit Detail'!C4:C193,1)/SUMIFS('190-Unit Detail'!F4:F193,'190-Unit Detail'!B4:B193,"Block 3",'190-Unit Detail'!C4:C193,1)) -> 0.92154459 | G37: =SUMIFS('190-Unit Detail'!N4:N193,'190-Unit Detail'!B4:B193,"Block 3",'190-Unit Detail'!C4:C193,1) -> 512
A38: Block 3 | B38: 2 | C38: =COUNTIFS('190-Unit Detail'!B4:B193,"Block 3",'190-Unit Detail'!C4:C193,2) -> 13 | D38: =SUMIFS('190-Unit Detail'!F4:F193,'190-Unit Detail'!B4:B193,"Block 3",'190-Unit Detail'!C4:C193,2) -> 6526 | E38: =SUMIFS('190-Unit Detail'!G4:G193,'190-Unit Detail'!B4:B193,"Block 3",'190-Unit Detail'!C4:C193,2) -> 5484 | F38: =IF(SUMIFS('190-Unit Detail'!F4:F193,'190-Unit Detail'!B4:B193,"Block 3",'190-Unit Detail'!C4:C193,2)=0,0,SUMIFS('190-Unit Detail'!G4:G193,'190-Unit Detail'!B4:B193,"Block 3",'190-Unit Detail'!C4:C193,2)/SUMIFS('190-Unit Detail'!F4:F193,'190-Unit Detail'!B4:B193,"Block 3",'190-Unit Detail'!C4:C193,2)) -> 0.84033098 | G38: =SUMIFS('190-Unit Detail'!N4:N193,'190-Unit Detail'!B4:B193,"Block 3",'190-Unit Detail'!C4:C193,2) -> 1042
A39: Block 4 | B39: 0 | C39: =COUNTIFS('190-Unit Detail'!B4:B193,"Block 4",'190-Unit Detail'!C4:C193,0) -> 14 | D39: =SUMIFS('190-Unit Detail'!F4:F193,'190-Unit Detail'!B4:B193,"Block 4",'190-Unit Detail'!C4:C193,0) -> 7112 | E39: =SUMIFS('190-Unit Detail'!G4:G193,'190-Unit Detail'!B4:B193,"Block 4",'190-Unit Detail'!C4:C193,0) -> 5996 | F39: =IF(SUMIFS('190-Unit Detail'!F4:F193,'190-Unit Detail'!B4:B193,"Block 4",'190-Unit Detail'!C4:C193,0)=0,0,SUMIFS('190-Unit Detail'!G4:G193,'190-Unit Detail'!B4:B193,"Block 4",'190-Unit Detail'!C4:C193,0)/SUMIFS('190-Unit Detail'!F4:F193,'190-Unit Detail'!B4:B193,"Block 4",'190-Unit Detail'!C4:C193,0)) -> 0.84308211 | G39: =SUMIFS('190-Unit Detail'!N4:N193,'190-Unit Detail'!B4:B193,"Block 4",'190-Unit Detail'!C4:C193,0) -> 1131
A40: Block 4 | B40: 1 | C40: =COUNTIFS('190-Unit Detail'!B4:B193,"Block 4",'190-Unit Detail'!C4:C193,1) -> 14 | D40: =SUMIFS('190-Unit Detail'!F4:F193,'190-Unit Detail'!B4:B193,"Block 4",'190-Unit Detail'!C4:C193,1) -> 7028 | E40: =SUMIFS('190-Unit Detail'!G4:G193,'190-Unit Detail'!B4:B193,"Block 4",'190-Unit Detail'!C4:C193,1) -> 5442 | F40: =IF(SUMIFS('190-Unit Detail'!F4:F193,'190-Unit Detail'!B4:B193,"Block 4",'190-Unit Detail'!C4:C193,1)=0,0,SUMIFS('190-Unit Detail'!G4:G193,'190-Unit Detail'!B4:B193,"Block 4",'190-Unit Detail'!C4:C193,1)/SUMIFS('190-Unit Detail'!F4:F193,'190-Unit Detail'!B4:B193,"Block 4",'190-Unit Detail'!C4:C193,1)) -> 0.77433125 | G40: =SUMIFS('190-Unit Detail'!N4:N193,'190-Unit Detail'!B4:B193,"Block 4",'190-Unit Detail'!C4:C193,1) -> 1604
A41: Block 4 | B41: 2 | C41: =COUNTIFS('190-Unit Detail'!B4:B193,"Block 4",'190-Unit Detail'!C4:C193,2) -> 14 | D41: =SUMIFS('190-Unit Detail'!F4:F193,'190-Unit Detail'!B4:B193,"Block 4",'190-Unit Detail'!C4:C193,2) -> 7028 | E41: =SUMIFS('190-Unit Detail'!G4:G193,'190-Unit Detail'!B4:B193,"Block 4",'190-Unit Detail'!C4:C193,2) -> 6833 | F41: =IF(SUMIFS('190-Unit Detail'!F4:F193,'190-Unit Detail'!B4:B193,"Block 4",'190-Unit Detail'!C4:C193,2)=0,0,SUMIFS('190-Unit Detail'!G4:G193,'190-Unit Detail'!B4:B193,"Block 4",'190-Unit Detail'!C4:C193,2)/SUMIFS('190-Unit Detail'!F4:F193,'190-Unit Detail'!B4:B193,"Block 4",'190-Unit Detail'!C4:C193,2)) -> 0.97225384 | G41: =SUMIFS('190-Unit Detail'!N4:N193,'190-Unit Detail'!B4:B193,"Block 4",'190-Unit Detail'!C4:C193,2) -> 195
A42: Block 5 | B42: 0 | C42: =COUNTIFS('190-Unit Detail'!B4:B193,"Block 5",'190-Unit Detail'!C4:C193,0) -> 14 | D42: =SUMIFS('190-Unit Detail'!F4:F193,'190-Unit Detail'!B4:B193,"Block 5",'190-Unit Detail'!C4:C193,0) -> 7112 | E42: =SUMIFS('190-Unit Detail'!G4:G193,'190-Unit Detail'!B4:B193,"Block 5",'190-Unit Detail'!C4:C193,0) -> 6297 | F42: =IF(SUMIFS('190-Unit Detail'!F4:F193,'190-Unit Detail'!B4:B193,"Block 5",'190-Unit Detail'!C4:C193,0)=0,0,SUMIFS('190-Unit Detail'!G4:G193,'190-Unit Detail'!B4:B193,"Block 5",'190-Unit Detail'!C4:C193,0)/SUMIFS('190-Unit Detail'!F4:F193,'190-Unit Detail'!B4:B193,"Block 5",'190-Unit Detail'!C4:C193,0)) -> 0.88540495 | G42: =SUMIFS('190-Unit Detail'!N4:N193,'190-Unit Detail'!B4:B193,"Block 5",'190-Unit Detail'!C4:C193,0) -> 815
A43: Block 5 | B43: 1 | C43: =COUNTIFS('190-Unit Detail'!B4:B193,"Block 5",'190-Unit Detail'!C4:C193,1) -> 14 | D43: =SUMIFS('190-Unit Detail'!F4:F193,'190-Unit Detail'!B4:B193,"Block 5",'190-Unit Detail'!C4:C193,1) -> 7028 | E43: =SUMIFS('190-Unit Detail'!G4:G193,'190-Unit Detail'!B4:B193,"Block 5",'190-Unit Detail'!C4:C193,1) -> 6438 | F43: =IF(SUMIFS('190-Unit Detail'!F4:F193,'190-Unit Detail'!B4:B193,"Block 5",'190-Unit Detail'!C4:C193,1)=0,0,SUMIFS('190-Unit Detail'!G4:G193,'190-Unit Detail'!B4:B193,"Block 5",'190-Unit Detail'!C4:C193,1)/SUMIFS('190-Unit Detail'!F4:F193,'190-Unit Detail'!B4:B193,"Block 5",'190-Unit Detail'!C4:C193,1)) -> 0.91605009 | G43: =SUMIFS('190-Unit Detail'!N4:N193,'190-Unit Detail'!B4:B193,"Block 5",'190-Unit Detail'!C4:C193,1) -> 590
A44: Block 5 | B44: 2 | C44: =COUNTIFS('190-Unit Detail'!B4:B193,"Block 5",'190-Unit Detail'!C4:C193,2) -> 14 | D44: =SUMIFS('190-Unit Detail'!F4:F193,'190-Unit Detail'!B4:B193,"Block 5",'190-Unit Detail'!C4:C193,2) -> 7028 | E44: =SUMIFS('190-Unit Detail'!G4:G193,'190-Unit Detail'!B4:B193,"Block 5",'190-Unit Detail'!C4:C193,2) -> 6229 | F44: =IF(SUMIFS('190-Unit Detail'!F4:F193,'190-Unit Detail'!B4:B193,"Block 5",'190-Unit Detail'!C4:C193,2)=0,0,SUMIFS('190-Unit Detail'!G4:G193,'190-Unit Detail'!B4:B193,"Block 5",'190-Unit Detail'!C4:C193,2)/SUMIFS('190-Unit Detail'!F4:F193,'190-Unit Detail'!B4:B193,"Block 5",'190-Unit Detail'!C4:C193,2)) -> 0.8863119 | G44: =SUMIFS('190-Unit Detail'!N4:N193,'190-Unit Detail'!B4:B193,"Block 5",'190-Unit Detail'!C4:C193,2) -> 799
...

Sheet 190-Unit Detail
A1: INSPECTION POINTS TO VISIT — 190 UNITS (per-unit detail)
A2: Total Points = 508 (ground) / 502 (above ground = 508 active points less 6 ground-only burglar-bar items, structurally absent upstairs). Items to Mark = Pending + NTS + Not Inst + Skipped. Already OK + Items to Mark = Total Points (row closes). POINTS TO VISIT = Items to Mark + Latents. Open Defects shown for context only — NOT added to PTV (they sit on the NTS items already counted). Source: /var/data/inspections.db, SNAP 2026-06-09 09:59 UTC.
A3: Unit | B3: Block | C3: Floor | D3: Cycle | E3: Status | F3: Total Points | G3: Already OK | H3: Pending | I3: NTS | J3: Not Inst | K3: Skipped | L3: Items to Mark | M3: Latents | N3: POINTS TO VISIT | O3: Open Defects (context — not in PTV)
A4: 101 | B4: Block 1 | C4: 1 | D4: C2 | E4: reviewed | F4: 502 | G4: 479 | H4: 15 | I4: 8 | J4: 0 | K4: 0 | L4: =H4+I4+J4+K4 -> 23 | M4: 0 | N4: =L4+M4 -> 23 | O4: 22
A5: 102 | B5: Block 1 | C5: 1 | D5: C2 | E5: reviewed | F5: 502 | G5: 475 | H5: 23 | I5: 4 | J5: 0 | K5: 0 | L5: =H5+I5+J5+K5 -> 27 | M5: 0 | N5: =L5+M5 -> 27 | O5: 28
A6: 201 | B6: Block 1 | C6: 2 | D6: C1 | E6: pending followup | F6: 502 | G6: 308 | H6: 0 | I6: 134 | J6: 6 | K6: 54 | L6: =H6+I6+J6+K6 -> 194 | M6: 0 | N6: =L6+M6 -> 194 | O6: 185
A7: 202 | B7: Block 1 | C7: 2 | D7: C1 | E7: pending followup | F7: 502 | G7: 362 | H7: 0 | I7: 86 | J7: 0 | K7: 54 | L7: =H7+I7+J7+K7 -> 140 | M7: 0 | N7: =L7+M7 -> 140 | O7: 112
A8: 248 | B8: Block 1 | C8: 2 | D8: C2 | E8: pending followup | F8: 502 | G8: 502 | H8: 0 | I8: 0 | J8: 0 | K8: 0 | L8: =H8+I8+J8+K8 -> 0 | M8: 0 | N8: =L8+M8 -> 0 | O8: 0
A9: 249 | B9: Block 1 | C9: 2 | D9: C2 | E9: pending followup | F9: 502 | G9: 356 | H9: 92 | I9: 0 | J9: 0 | K9: 54 | L9: =H9+I9+J9+K9 -> 146 | M9: 1 | N9: =L9+M9 -> 147 | O9: 1
A10: 250 | B10: Block 1 | C10: 2 | D10: C3 | E10: submitted | F10: 502 | G10: 478 | H10: 0 | I10: 24 | J10: 0 | K10: 0 | L10: =H10+I10+J10+K10 -> 24 | M10: 0 | N10: =L10+M10 -> 24 | O10: 0
A11: 251 | B11: Block 1 | C11: 2 | D11: C2 | E11: pending followup | F11: 502 | G11: 497 | H11: 0 | I11: 5 | J11: 0 | K11: 0 | L11: =H11+I11+J11+K11 -> 5 | M11: 0 | N11: =L11+M11 -> 5 | O11: 1
A12: 144 | B12: Block 2 | C12: 1 | D12: C2 | E12: pending followup | F12: 502 | G12: 367 | H12: 127 | I12: 8 | J12: 0 | K12: 0 | L12: =H12+I12+J12+K12 -> 135 | M12: 0 | N12: =L12+M12 -> 135 | O12: 43
A13: 145 | B13: Block 2 | C13: 1 | D13: C2 | E13: pending followup | F13: 502 | G13: 377 | H13: 118 | I13: 7 | J13: 0 | K13: 0 | L13: =H13+I13+J13+K13 -> 125 | M13: 0 | N13: =L13+M13 -> 125 | O13: 15
A14: 146 | B14: Block 2 | C14: 1 | D14: C2 | E14: pending followup | F14: 502 | G14: 401 | H14: 99 | I14: 2 | J14: 0 | K14: 0 | L14: =H14+I14+J14+K14 -> 101 | M14: 0 | N14: =L14+M14 -> 101 | O14: 1
A15: 147 | B15: Block 2 | C15: 1 | D15: C2 | E15: pending followup | F15: 502 | G15: 379 | H15: 116 | I15: 7 | J15: 0 | K15: 0 | L15: =H15+I15+J15+K15 -> 123 | M15: 0 | N15: =L15+M15 -> 123 | O15: 7
... A193: 269 | B193: Block 7 | C193: 2 | D193: C2 | E193: pending followup | F193: 502 | G193: 499 | H193: 0 | I193: 3 | J193: 0 | K193: 0 | L193: =H193+I193+J193+K193 -> 3 | M193: 0 | N193: =L193+M193 -> 3 | O193: 0
A194: PROJECT TOTAL | F194: =SUM(F4:F193) -> 95716 | G194: =SUM(G4:G193) -> 83046 | H194: =SUM(H4:H193) -> 5881 | I194: =SUM(I4:I193) -> 2140 | J194: =SUM(J4:J193) -> 12 | K194: =SUM(K4:K193) -> 4637 | L194: =SUM(L4:L193) -> 12670 | M194: =SUM(M4:M193) -> 69 | ... O194: =SUM(O4:O193) -> 2464
